Workbook

Sheet Submission_Info
A1: School Name: Datamex College of Saint Adeline
A3: Examination: Data Analysis Midterm Exam (Hands-On Examination)
A5: Student Name: Marcial Lawrence Jr V. Caronan
A7: Year / Section: 4th Year BSIT Set A
A9: Date: September 17, 2026

Sheet Data_Dictionary
A1: Variable / Column Name | B1: Data Type | C1: Description
A2: Transaction_ID | B2: Text / Alphanumeric | C2: Unique identification code assigned to each customer transaction (e.g., T1000).
A3: Day | B3: Numerical (Integer) | C3: The sequential day number of the operation/recording period (e.g., Day 1 to Day 50).
A4: Day_of_Week | B4: Text | C4: The specific day of the week when the transaction occurred (e.g., Mon, Tue, Wed, etc.).
A5: Customer_Age | B5: Numerical (Integer) | C5: The age of the customer making the transaction.
A6: Gender | B6: Text | C6: The gender of the customer (e.g., Male, Female).
A7: Student | B7: Text (Yes / No) | C7: Indicates whether the customer is a student (Yes) or a non-student (No).
A8: Internet_Hours | B8: Numerical (Integer) | C8: The total number of hours the customer spent using the internet service.
A9: Printing_Pages | B9: Numerical (Integer) | C9: The number of pages printed by the customer during the transaction.
A10: Scanning_Pages | B10: Numerical (Integer) | C10: The number of pages scanned by the customer during the transaction.
A11: Gaming | B11: Text (Yes / No) | C11: Indicates whether the customer used the gaming service (Yes) or not (No).
A12: Total_Sales | B12: Numerical (Integer / Currency) | C12: The total monetary value or revenue generated from the transaction.

Sheet Raw_Data
A1: Transaction_ID | B1: Day | C1: Day_of_Week | D1: Costumer_Age | E1: Gender | F1: Student | G1: Internet_Hours | H1: Printing_Pages | I1: Scanning_Pages | J1: Gaming | K1: Total_Sales
A2: T1000 | B2: 1 | C2: Mon | D2: 29 | E2: Male | F2: Yes | G2: 5 | H2: 11 | I2: 4 | J2: No | K2: 220
A3: T1001 | B3: 2 | C3: Tue | D3: 22 | E3: Female | F3: Yes | G3: 8 | H3: 0 | I3: 7 | J3: No | K3: 270
A4: T1002 | B4: 3 | C4: Wed | D4: 27 | E4: Female | F4: Yes | G4: 7 | H4: 1 | I4: 0 | J4: No | K4: 180
A5: T1003 | B5: 4 | C5: Thu | D5: 18 | E5: Female | F5: No | G5: 3 | H5: 2 | I5: 6 | J5: Yes | K5: 205
A6: T1004 | B6: 5 | C6: Fri | D6: 18 | E6: Female | F6: Yes | G6: 1 | H6: 10 | I6: 6 | J6: Yes | K6: 195
A7: T1005 | B7: 6 | C7: Sat | D7: 19 | E7: Female | F7: Yes | G7: 4 | H7: 10 | I7: 1 | J7: No | K7: 160
A8: T1006 | B8: 7 | C8: Sun | D8: 18 | E8: Female | F8: No | G8: 3 | H8: 10 | I8: 4 | J8: Yes | K8: 225
A9: T1007 | B9: 8 | C9: Mon | D9: 29 | E9: Male | F9: Yes | G9: 4 | H9: 6 | I9: 2 | J9: No | K9: 150
A10: T1008 | B10: 9 | C10: Tue | D10: 18 | E10: Male | F10: Yes | G10: 1 | H10: 15 | I10: 5 | J10: No | K10: 150
A11: T1009 | B11: 10 | C11: Wed | D11: 33 | E11: Female | F11: Yes | G11: 6 | H11: 0 | I11: 5 | J11: No | K11: 200
A12: T1010 | B12: 11 | C12: Thu | D12: 23 | E12: Male | F12: Yes | G12: 3 | H12: 14 | I12: 6 | J12: No | K12: 205
A13: T1011 | B13: 12 | C13: Fri | D13: 28 | E13: Female | F13: Yes | G13: 4 | H13: 6 | I13: 6 | J13: Yes | K13: 250
... A51: T1049 | B51: 50 | C51: Mon | D51: 35 | E51: Male | F51: Yes | G51: 4 | H51: 12 | I51: 6 | J51: No | K51: 220

Sheet Exam_Tasks
A1: Student Name: Caronan, Marcial Lawrence Jr V.
A2: Year / Section: 4th year BSIT Set A
A3: Date: September 17, 2026
A5: Main Student Tasks
A7: 1. Inspect and clean the raw data
A8: I checked all columns in the Raw_Data sheet row by row to look for typing errors, incorrect formatting, or strange characters. I used Excel's Filter tool on the header row to review the values in each column and make sure everything looked correct and clean.
A10: 2. Identify and handle missing values
A11: I used Excel’s Go To Special then Blanks feature to instantly find any missing or empty cells in the spreadsheet. Once located, I filled in the missing values properly (such as entering zeroes or placeholder text) so they wouldn't mess up my calculations.
A13: 3. Calculate descriptive statistics
A14: Descriptive Statistic
A15: Values | B15: Total | C15: Average | D15: Median | E15: Minimum | F15: Maximum
A16: Customer Age | B16: =SUM(Raw_Data!D2:D51) -> 1331 | C16: =AVERAGE(Raw_Data!D2:D51) -> 26.62 | D16: =MEDIAN(Raw_Data!D2:D51) -> 27.5 | E16: =MIN(Raw_Data!D2:D51) -> 17 | F16: =MAX(Raw_Data!D2:D51) -> 35
A17: Sales | B17: =SUM(Raw_Data!K2:K51) -> 9690 | C17: =AVERAGE(Raw_Data!K2:K51) -> 193.8 | D17: =MEDIAN(Raw_Data!K2:K51) -> 202.5 | E17: =MIN(Raw_Data!K2:K51) -> 65 | F17: =MAX(Raw_Data!K2:K51) -> 365
A18: Internet Hours | B18: =SUM(Raw_Data!G2:G51) -> 199 | C18: =AVERAGE(Raw_Data!G2:G51) -> 3.98 | D18: =MEDIAN(Raw_Data!G2:G51) -> 4 | E18: =MIN(Raw_Data!G2:G51) -> 1 | F18: =MAX(Raw_Data!G2:G51) -> 8
A19: Printing Pages | B19: =SUM(Raw_Data!H2:H51) -> 415 | C19: =AVERAGE(Raw_Data!H2:H51) -> 8.3 | D19: =MEDIAN(Raw_Data!H2:H51) -> 9.5 | E19: =MIN(Raw_Data!H2:H51) -> 0 | F19: =MAX(Raw_Data!H2:H51) -> 15
A20: Scanning Pages | B20: =SUM(Raw_Data!I2:I51) -> 180 | C20: =AVERAGE(Raw_Data!I2:I51) -> 3.6 | D20: =MEDIAN(Raw_Data!I2:I51) -> 3.5 | E20: =MIN(Raw_Data!I2:I51) -> 0 | F20: =MAX(Raw_Data!I2:I51) -> 7
A22: 4 Calculate total, mean, median, minimum, and maximum sales.
A24: Sale Statistic
A25: Total | B25: =SUM(Raw_Data!K2:K51) -> 9690
A26: Mean | B26: =AVERAGE(Raw_Data!K2:K51) -> 193.8
A27: Median | B27: =MEDIAN(Raw_Data!K2:K51) -> 202.5
A28: Minimum | B28: =MIN(Raw_Data!K2:K51) -> 65
A29: Maximum | B29: =MAX(Raw_Data!K2:K51) -> 365
A31: 5. Compare student vs. non-student customers
A33: Costumers | B33: Total Costumers | C33: Total Sales | D33: Average Sale | E33: Internet Hours | F33: Printing Page | G33: Scanning Page | H33: Gaming | I33: Non-Gaming | J33: Average Costumer Age
A34: Students | B34: =COUNTIF(Raw_Data!F2:F51, "Yes") -> 38 | C34: =SUMIF(Raw_Data!F2:F51, "Yes", Raw_Data!K2:K51) -> 7370 | D34: =AVERAGEIF(Raw_Data!F2:F51, "Yes", Raw_Data!K2:K51) -> 193.94737 | E34: =SUMIF(Raw_Data!F2:F51, "Yes", Raw_Data!G2:G51) -> 152 | F34: =SUMIF(Raw_Data!F2:F51, "Yes", Raw_Data!H2:H51) -> 312 | G34: =SUMIF(Raw_Data!F2:F51, "Yes", Raw_Data!I2:I51) -> 141 | H34: =COUNTIFS(Raw_Data!F2:F51, "yes", Raw_Data!J2:J51, "yes") -> 10 | I34: =COUNTIFS(Raw_Data!F2:F51, "yes", Raw_Data!J2:J51, "no") -> 28 | J34: =AVERAGEIF(Raw_Data!F2:F51, "Yes", Raw_Data!D2:D51) -> 26.868421
A35: Non-Students | B35: =COUNTIF(Raw_Data!F2:F51, "No") -> 12 | C35: =SUMIF(Raw_Data!F2:F51, "No", Raw_Data!K2:K51) -> 2320 | D35: =AVERAGEIF(Raw_Data!F2:F51, "No", Raw_Data!K2:K51) -> 193.33333 | E35: =SUMIF(Raw_Data!F2:F51, "No", Raw_Data!G2:G51) -> 47 | F35: =SUMIF(Raw_Data!F2:F51, "No", Raw_Data!H2:H51) -> 103 | G35: =SUMIF(Raw_Data!F2:F51, "No", Raw_Data!I2:I51) -> 39 | H35: =COUNTIFS(Raw_Data!F2:F51, "no", Raw_Data!J2:J51, "yes") -> 4 | I35: =COUNTIFS(Raw_Data!F2:F51, "no", Raw_Data!J2:J51, "no") -> 8 | J35: =AVERAGEIF(Raw_Data!F2:F51, "No", Raw_Data!D2:D51) -> 25.833333
A37: 6. Analyze sales by day of the week
A38: Days of Week | B38: Sum of Total_Sales
A39: Sun | B39: 1500
A40: Mon | B40: 1500
A41: Tue | B41: 1410
A42: Wed | B42: 1215
A43: Thu | B43: 1305
A44: Fri | B44: 1450
A45: Sat | B45: 1310
A46: (blank)
A47: Grand Total | B47: 9690
A48: Monday and Sunday has the Highest Sales of the week, while Wednesday has the lowest Sales
A50: 7. Determine the highest-revenue service
...

Sheet Recommendations
A1: 12. Provide evidence-based business recommendations
A2: Based on the comprehensive analysis of the computer shop's operations, customer demographics, and service performance, the following evidence-based business recommendations are proposed to optimize revenue and improve operational efficiency:
A3: Maximize Internet-Driven Revenue Bundles:
A4: Evidence: Task 10 reveals a strong positive correlation of
A5: between Internet Hours and Total Sales, and Task 7 shows heavy utilization across services.
A6: Recommendation: Management should introduce promotional packages or tiered bundles like discounted printing or gaming bundles for customers who purchase extended internet hours, to further leverage this primary driver of customer spending.
A7: Capitalize on Peak Days:
A8: Evidence: Task 6 indicates that Sunday and Monday generate the highest sales of
A9: each, while Wednesday experiences the lowest revenue of
A10: Recommendation: To balance out weekly traffic, implement off-peak promotional rates or special discounts on Wednesdays to stimulate customer volume during slower mid-week operations.
A11: Target Core Demographics (Students):
A12: Evidence: Task 5 and Task 8 show that students comprise much of the customer base as
... A18: Recommendation: Ensure that printers are regularly maintained, stocked with paper and ink, and placed in an accessible area to prevent bottlenecks during peak transaction hours, protecting the shop's most frequent revenue-generating service.
